{
  "schema_version": "1.4.0",
  "id": "GHSA-jrfm-2h82-xg28",
  "modified": "2024-04-22T18:55:59Z",
  "published": "2023-07-06T21:30:28Z",
  "aliases": [
    "CVE-2023-29824"
  ],
  "summary": "Use after free in SciPy (this is a bogus CVE)",
  "details": "A use-after-free issue was discovered in Py_FindObjects() function in SciPy versions prior to 1.8.0.\n\nNOTE: the vendor and discoverer indicate that this is not a security issue.\n\nThis is part of the bogus CVE phenomenon and in these advisories currently there seems no way to reflect the \"Disouted\" status of the CVEs as NVD shows.",
  "severity": [
    {
      "type": "CVSS_V3",
      "score": "CVSS:3.1/AV:N/AC:L/PR:N/UI:N/S:U/C:H/I:H/A:H"
    }
  ],
  "affected": [
    {
      "package": {
        "ecosystem": "PyPI",
        "name": "scipy"
      },
      "ranges": [
        {
          "type": "ECOSYSTEM",
          "events": [
            {
              "introduced": "0"
            },
            {
              "fixed": "1.8.0"
            }
          ]
        }
      ]
    }
  ],
  "references": [
    {
      "type": "ADVISORY",
      "url": "https://nvd.nist.gov/vuln/detail/CVE-2023-29824"
    },
    {
      "type": "WEB",
      "url": "https://github.com/scipy/scipy/issues/14713"
    },
    {
      "type": "WEB",
      "url": "https://github.com/scipy/scipy/issues/14713#issuecomment-1629468565"
    },
    {
      "type": "WEB",
      "url": "https://github.com/scipy/scipy/pull/15013"
    },
    {
      "type": "WEB",
      "url": "https://github.com/scipy/scipy/commit/e32fc2329d3dd23298725153c5b2cc7fcd0f14f1"
    },
    {
      "type": "WEB",
      "url": "http://www.square16.org/achievement/cve-2023-29824"
    }
  ],
  "database_specific": {
    "cwe_ids": [
      "CWE-416"
    ],
    "severity": "CRITICAL",
    "github_reviewed": true,
    "github_reviewed_at": "2024-04-22T18:55:58Z",
    "nvd_published_at": "2023-07-06T21:15:09Z"
  }
}