{
  "schema_version": "1.2.0",
  "id": "GHSA-chqf-hx79-gxc6",
  "modified": "2022-07-26T13:54:15Z",
  "published": "2022-05-17T02:58:54Z",
  "aliases": [
    "CVE-2017-5992"
  ],
  "summary": "Improper Restriction of XML External Entity Reference in Openpyxl",
  "details": "Openpyxl 2.4.1 resolves external entities by default, which allows remote attackers to conduct XXE attacks via a crafted .xlsx document.",
  "severity": [
    {
      "type": "CVSS_V3",
      "score": "CVSS:3.0/AV:L/AC:L/PR:N/UI:R/S:C/C:H/I:N/A:H"
    }
  ],
  "affected": [
    {
      "package": {
        "ecosystem": "PyPI",
        "name": "openpyxl"
      },
      "ranges": [
        {
          "type": "ECOSYSTEM",
          "events": [
            {
              "introduced": "0"
            },
            {
              "fixed": "2.4.2"
            }
          ]
        }
      ],
      "database_specific": {
        "last_known_affected_version_range": "<= 2.4.1"
      }
    }
  ],
  "references": [
    {
      "type": "ADVISORY",
      "url": "https://nvd.nist.gov/vuln/detail/CVE-2017-5992"
    },
    {
      "type": "WEB",
      "url": "https://bitbucket.org/openpyxl/openpyxl/commits/3b4905f428e1"
    },
    {
      "type": "WEB",
      "url": "https://bitbucket.org/openpyxl/openpyxl/issues/749"
    },
    {
      "type": "WEB",
      "url": "https://foss.heptapod.net/openpyxl/openpyxl/-/commit/7fe678fd89fd"
    },
    {
      "type": "WEB",
      "url": "https://foss.heptapod.net/openpyxl/openpyxl/-/issues/749"
    },
    {
      "type": "WEB",
      "url": "https://bugs.debian.org/cgi-bin/bugreport.cgi?bug=854442"
    },
    {
      "type": "WEB",
      "url": "http://www.openwall.com/lists/oss-security/2017/02/07/5"
    }
  ],
  "database_specific": {
    "cwe_ids": [
      "CWE-611"
    ],
    "severity": "HIGH",
    "github_reviewed": true
  }
}