{
  "schema_version": "1.2.0",
  "id": "GHSA-4r65-35qq-ch8j",
  "modified": "2022-03-20T06:45:49Z",
  "published": "2022-03-04T00:00:17Z",
  "aliases": [
    "CVE-2021-3620"
  ],
  "summary": "Ansible: ansible-connection module discloses sensitive info in traceback error message",
  "details": "A flaw was found in Ansible Engine's ansible-connection module, where sensitive information such as the Ansible user credentials is disclosed by default in the traceback error message. The highest threat from this vulnerability is to confidentiality.",
  "severity": [
    {
      "type": "CVSS_V3",
      "score": "CVSS:3.1/AV:L/AC:L/PR:L/UI:N/S:U/C:H/I:N/A:N"
    }
  ],
  "affected": [
    {
      "package": {
        "ecosystem": "PyPI",
        "name": "ansible"
      },
      "ranges": [
        {
          "type": "ECOSYSTEM",
          "events": [
            {
              "introduced": "0"
            },
            {
              "fixed": "2.9.27"
            }
          ]
        }
      ]
    }
  ],
  "references": [
    {
      "type": "ADVISORY",
      "url": "https://nvd.nist.gov/vuln/detail/CVE-2021-3620"
    },
    {
      "type": "WEB",
      "url": "https://github.com/ansible/ansible/commit/fe28767970c8ec62aabe493c46b53a5de1e5fac0"
    },
    {
      "type": "WEB",
      "url": "https://bugzilla.redhat.com/show_bug.cgi?id=1975767"
    },
    {
      "type": "WEB",
      "url": "https://github.com/ansible/ansible/blob/stable-2.9/changelogs/CHANGELOG-v2.9.rst#security-fixes"
    }
  ],
  "database_specific": {
    "cwe_ids": [
      "CWE-209"
    ],
    "severity": "MODERATE",
    "github_reviewed": false
  }
}